<?xml version="1.0" ?>
<!-- =================================================================================== -->
<!-- |    This document was autogenerated by xacro from combined.xacro                 | -->
<!-- |    EDITING THIS FILE BY HAND IS NOT RECOMMENDED                                 | -->
<!-- =================================================================================== -->
<robot name="hand_with_arm">
  <link name="base_link">
    <inertial>
      <origin rpy="0 0 0" xyz="-1.4795E-13 0.0015384 0.020951"/>
      <mass value="0.83419"/>
      <inertia ixx="0.0014414" ixy="7.8809E-15" ixz="8.5328E-16" iyy="0.0013542" iyz="-1.4364E-05" izz="0.0024659"/>
    </inertial>
    <visual>
      <origin rpy="0 0 0" xyz="0 0 0"/>
      <geometry>
        <mesh filename="package://aubo_description/meshes/aubo_i5/visual/base_link.DAE"/>
      </geometry>
      <material name="">
        <color rgba="1 1 1 1"/>
      </material>
    </visual>
    <collision>
      <origin rpy="0 0 0" xyz="0 0 0"/>
      <geometry>
        <mesh filename="package://aubo_description/meshes/aubo_i5/collision/base_link.STL"/>
      </geometry>
    </collision>
  </link>
  <link name="shoulder_Link">
    <inertial>
      <origin rpy="0 0 0" xyz="3.2508868974735E-07 0.00534955349296065 -0.00883689325611056"/>
      <mass value="1.57658348693929"/>
      <inertia ixx="0.0040640448663128" ixy="0" ixz="0" iyy="0.00392863238466817" iyz="-0.000160151642851425" izz="0.0030869857349184"/>
    </inertial>
    <visual>
      <origin rpy="0 0 0" xyz="0 0 0"/>
      <geometry>
        <mesh filename="package://aubo_description/meshes/aubo_i5/visual/shoulder_Link.DAE"/>
      </geometry>
      <material name="">
        <color rgba="1 1 1 1"/>
      </material>
    </visual>
    <collision>
      <origin rpy="0 0 0" xyz="0 0 0"/>
      <geometry>
        <mesh filename="package://aubo_description/meshes/aubo_i5/collision/shoulder_Link.STL"/>
      </geometry>
    </collision>
  </link>
  <joint name="shoulder_joint" type="revolute">
    <origin rpy="0 0 3.1416" xyz="0 0 0.122"/>
    <parent link="base_link"/>
    <child link="shoulder_Link"/>
    <axis xyz="0 0 1"/>
    <limit effort="0" lower="-3.05" upper="3.05" velocity="0"/>
  </joint>
  <link name="upperArm_Link">
    <inertial>
      <origin rpy="0 0 0" xyz="0.203996646979614 2.01304585036544E-10 0.0127641545395984"/>
      <mass value="4.04175782265494"/>
      <inertia ixx="0.00965399211106204" ixy="0" ixz="0" iyy="0.144993869035655" iyz="0" izz="0.142607184038966"/>
    </inertial>
    <visual>
      <origin rpy="0 0 0" xyz="0 0 0"/>
      <geometry>
        <mesh filename="package://aubo_description/meshes/aubo_i5/visual/upperArm_Link.DAE"/>
      </geometry>
      <material name="">
        <color rgba="1 1 1 1"/>
      </material>
    </visual>
    <collision>
      <origin rpy="0 0 0" xyz="0 0 0"/>
      <geometry>
        <mesh filename="package://aubo_description/meshes/aubo_i5/collision/upperArm_Link.STL"/>
      </geometry>
    </collision>
  </link>
  <joint name="upperArm_joint" type="revolute">
    <origin rpy="-1.5708 -1.5708 0" xyz="0 0.1215 0"/>
    <parent link="shoulder_Link"/>
    <child link="upperArm_Link"/>
    <axis xyz="0 0 1"/>
    <limit effort="0" lower="-3.05" upper="3.05" velocity="0"/>
  </joint>
  <link name="foreArm_Link">
    <inertial>
      <origin rpy="0 0 0" xyz="0.188922115560337 6.78882434739072E-07 0.0981026740461557"/>
      <mass value="2.27145669098343"/>
      <inertia ixx="0.00214322284946289" ixy="0" ixz="-0.00073120631553383" iyy="0.0443926090878205" iyz="0" izz="0.0441273797128365"/>
    </inertial>
    <visual>
      <origin rpy="0 0 0" xyz="0 0 0"/>
      <geometry>
        <mesh filename="package://aubo_description/meshes/aubo_i5/visual/foreArm_Link.DAE"/>
      </geometry>
      <material name="">
        <color rgba="1 1 1 1"/>
      </material>
    </visual>
    <collision>
      <origin rpy="0 0 0" xyz="0 0 0"/>
      <geometry>
        <mesh filename="package://aubo_description/meshes/aubo_i5/collision/foreArm_Link.STL"/>
      </geometry>
    </collision>
  </link>
  <joint name="foreArm_joint" type="revolute">
    <origin rpy="-3.1416 -5.1632E-18 -5.459E-16" xyz="0.408 0 0"/>
    <parent link="upperArm_Link"/>
    <child link="foreArm_Link"/>
    <axis xyz="0 0 1"/>
    <limit effort="0" lower="-3.05" upper="3.05" velocity="0"/>
  </joint>
  <link name="wrist1_Link">
    <inertial>
      <origin rpy="0 0 0" xyz="7.54205137428592E-07 0.0062481254331257 -0.00392367464072373"/>
      <mass value="0.500477539188764"/>
      <inertia ixx="0.00071194605962081" ixy="0" ixz="0" iyy="0.00040588242872958" iyz="-2.30808694377512E-05" izz="0.000685574004861334"/>
    </inertial>
    <visual>
      <origin rpy="0 0 0" xyz="0 0 0"/>
      <geometry>
        <mesh filename="package://aubo_description/meshes/aubo_i5/visual/wrist1_Link.DAE"/>
      </geometry>
      <material name="">
        <color rgba="1 1 1 1"/>
      </material>
    </visual>
    <collision>
      <origin rpy="0 0 0" xyz="0 0 0"/>
      <geometry>
        <mesh filename="package://aubo_description/meshes/aubo_i5/collision/wrist1_Link.STL"/>
      </geometry>
    </collision>
  </link>
  <joint name="wrist1_joint" type="revolute">
    <origin rpy="3.1416 -1.8323E-15 1.5708" xyz="0.376 0 0"/>
    <parent link="foreArm_Link"/>
    <child link="wrist1_Link"/>
    <axis xyz="0 0 1"/>
    <limit effort="0" lower="-3.05" upper="3.05" velocity="0"/>
  </joint>
  <link name="wrist2_Link">
    <inertial>
      <origin rpy="0 0 0" xyz="-7.54207620578635E-07 -0.00624812542617262 -0.00392367464115684"/>
      <mass value="0.500477539245988"/>
      <inertia ixx="0.00071194605981829" ixy="0" ixz="0" iyy="0.000405882428755442" iyz="2.30808694515886E-05" izz="0.000685574005112107"/>
    </inertial>
    <visual>
      <origin rpy="0 0 0" xyz="0 0 0"/>
      <geometry>
        <mesh filename="package://aubo_description/meshes/aubo_i5/visual/wrist2_Link.DAE"/>
      </geometry>
      <material name="">
        <color rgba="1 1 1 1"/>
      </material>
    </visual>
    <collision>
      <origin rpy="0 0 0" xyz="0 0 0"/>
      <geometry>
        <mesh filename="package://aubo_description/meshes/aubo_i5/collision/wrist2_Link.STL"/>
      </geometry>
    </collision>
  </link>
  <joint name="wrist2_joint" type="revolute">
    <origin rpy="-1.5708 -1.8709E-15 -1.6653E-16" xyz="0 0.1025 0"/>
    <parent link="wrist1_Link"/>
    <child link="wrist2_Link"/>
    <axis xyz="0 0 1"/>
    <limit effort="0" lower="-3.05" upper="3.05" velocity="0"/>
  </joint>
  <link name="wrist3_Link">
    <inertial>
      <origin rpy="0 0 0" xyz="3.92048778449938E-10 0.000175788057281467 -0.0213294490706684"/>
      <mass value="0.158309554874285"/>
      <inertia ixx="7.31376196034769E-05" ixy="0" ixz="0" iyy="7.19528188876563E-05" iyz="0" izz="0.000108772439051422"/>
    </inertial>
    <visual>
      <origin rpy="0 0 0" xyz="0 0 0"/>
      <geometry>
        <mesh filename="package://aubo_description/meshes/aubo_i5/visual/wrist3_Link.DAE"/>
      </geometry>
      <material name="">
        <color rgba="1 1 1 1"/>
      </material>
    </visual>
    <collision>
      <origin rpy="0 0 0" xyz="0 0 0"/>
      <geometry>
        <mesh filename="package://aubo_description/meshes/aubo_i5/collision/wrist3_Link.STL"/>
      </geometry>
    </collision>
  </link>
  <joint name="wrist3_joint" type="revolute">
    <origin rpy="1.5708 0 1.7907E-15" xyz="0 -0.094 0"/>
    <parent link="wrist2_Link"/>
    <child link="wrist3_Link"/>
    <axis xyz="0 0 1"/>
    <limit effort="0" lower="-3.05" upper="3.05" velocity="0"/>
  </joint>
  <link name="world"/>
  <joint name="world_joint" type="fixed">
    <parent link="world"/>
    <child link="base_link"/>
    <origin rpy="0.0 0.0 0.0" xyz="0.0 0.0 0.0"/>
  </joint>
  <link name="base_link">
    <inertial>
      <origin rpy="0 0 0" xyz="0.00288917703400745 7.19298575992736E-08 0.0333943413697345"/>
      <mass value="0.0405673074248041"/>
      <inertia ixx="3.05405058204204E-05" ixy="-9.17701530382059E-12" ixz="-2.28215750329719E-06" iyy="2.99406334813428E-05" iyz="5.05819828519376E-11" izz="1.29896650650468E-05"/>
    </inertial>
    <visual>
      <origin rpy="0 0 0" xyz="0 0 0"/>
      <geometry>
        <mesh filename="package://Assem_w_tip_w_wrist/meshes/base_link.STL"/>
      </geometry>
      <material name="">
        <color rgba="1 1 1 1"/>
      </material>
    </visual>
    <collision>
      <origin rpy="0 0 0" xyz="0 0 0"/>
      <geometry>
        <mesh filename="package://Assem_w_tip_w_wrist/meshes/base_link.STL"/>
      </geometry>
    </collision>
  </link>
  <link name="Palm">
    <inertial>
      <origin rpy="0 0 0" xyz="-0.00100228247291861 0.0713109339067146 -0.00174502462719912"/>
      <mass value="0.120926471921812"/>
      <inertia ixx="0.000138610425454301" ixy="-4.62786158151152E-06" ixz="2.20807343346201E-06" iyy="0.000101897977536037" iyz="-2.30882115787054E-06" izz="0.000192936318502003"/>
    </inertial>
    <visual>
      <origin rpy="0 0 0" xyz="0 0 0"/>
      <geometry>
        <mesh filename="package://Assem_w_tip_w_wrist/meshes/Palm.STL"/>
      </geometry>
      <material name="">
        <color rgba="1 1 1 1"/>
      </material>
    </visual>
    <collision>
      <origin rpy="0 0 0" xyz="0 0 0"/>
      <geometry>
        <mesh filename="package://Assem_w_tip_w_wrist/meshes/Palm.STL"/>
      </geometry>
    </collision>
  </link>
  <link name="I_B_MCP">
    <inertial>
      <origin rpy="0 0 0" xyz="-0.000141741869560293 0.0074142743318362 0.00334888740628136"/>
      <mass value="0.00533430654578869"/>
      <inertia ixx="1.03059674811244E-06" ixy="2.85499977000514E-09" ixz="5.92073904839143E-09" iyy="6.30910052491092E-07" iyz="-3.26746504704581E-07" izz="8.35249912431195E-07"/>
    </inertial>
    <visual>
      <origin rpy="0 0 0" xyz="0 0 0"/>
      <geometry>
        <mesh filename="package://Assem_w_tip_w_wrist/meshes/I_B_MCP.STL"/>
      </geometry>
      <material name="">
        <color rgba="0.698039215686274 0.698039215686274 0.698039215686274 1"/>
      </material>
    </visual>
    <collision>
      <origin rpy="0 0 0" xyz="0 0 0"/>
      <geometry>
        <mesh filename="package://Assem_w_tip_w_wrist/meshes/I_B_MCP.STL"/>
      </geometry>
    </collision>
  </link>
  <joint name="Index_Below_MCP" type="revolute">
    <origin rpy="3.14159265358979 0 3.14159265358979" xyz="0.0314999999997207 0.140450000000007 0"/>
    <parent link="Palm"/>
    <child link="I_B_MCP"/>
    <axis xyz="0 0 1"/>
    <limit effort="0" lower="0" upper="0.4666" velocity="0"/>
  </joint>
  <link name="I_MCP">
    <inertial>
      <origin rpy="0 0 0" xyz="-1.74798426278155E-05 0.0124250684933012 0.0058426333833799"/>
      <mass value="0.00275593740944754"/>
      <inertia ixx="3.71397800153596E-07" ixy="-4.41719116223258E-11" ixz="5.12329061713431E-11" iyy="2.52621011381552E-07" iyz="4.71521203210919E-08" izz="3.66972791021968E-07"/>
    </inertial>
    <visual>
      <origin rpy="0 0 0" xyz="0 0 0"/>
      <geometry>
        <mesh filename="package://Assem_w_tip_w_wrist/meshes/I_MCP.STL"/>
      </geometry>
      <material name="">
        <color rgba="0.796078431372549 0.823529411764706 0.937254901960784 1"/>
      </material>
    </visual>
    <collision>
      <origin rpy="0 0 0" xyz="0 0 0"/>
      <geometry>
        <mesh filename="package://Assem_w_tip_w_wrist/meshes/I_MCP.STL"/>
      </geometry>
    </collision>
  </link>
  <joint name="Index_MCP" type="revolute">
    <origin rpy="3.14159265358979 0 3.14159265358979" xyz="0 0.0280000000000001 0.00795476324525228"/>
    <parent link="I_B_MCP"/>
    <child link="I_MCP"/>
    <axis xyz="-1 0 0"/>
    <limit effort="0" lower="-1.8002" upper="0" velocity="0"/>
  </joint>
  <link name="I_PIP">
    <inertial>
      <origin rpy="0 0 0" xyz="-1.89088826897318E-05 0.0102468342925393 0.00623016626774232"/>
      <mass value="0.00240650780281676"/>
      <inertia ixx="2.39240219965935E-07" ixy="-3.25872058619951E-11" ixz="3.63121382835939E-11" iyy="2.04216614716598E-07" iyz="3.40669686531923E-09" izz="2.34950639926256E-07"/>
    </inertial>
    <visual>
      <origin rpy="0 0 0" xyz="0 0 0"/>
      <geometry>
        <mesh filename="package://Assem_w_tip_w_wrist/meshes/I_PIP.STL"/>
      </geometry>
      <material name="">
        <color rgba="0.796078431372549 0.823529411764706 0.937254901960784 1"/>
      </material>
    </visual>
    <collision>
      <origin rpy="0 0 0" xyz="0 0 0"/>
      <geometry>
        <mesh filename="package://Assem_w_tip_w_wrist/meshes/I_PIP.STL"/>
      </geometry>
    </collision>
  </link>
  <joint name="Index_PIP" type="revolute">
    <origin rpy="0 0 0" xyz="0 0.0349845407392165 4.41133227610524E-05"/>
    <parent link="I_MCP"/>
    <child link="I_PIP"/>
    <axis xyz="-1 0 0"/>
    <limit effort="0" lower="-1.3104" upper="0" velocity="0"/>
  </joint>
  <link name="I_DIP">
    <inertial>
      <origin rpy="0 0 0" xyz="-1.79514642293377E-05 0.0186542949904827 0.00887453782729761"/>
      <mass value="0.00401062210067862"/>
      <inertia ixx="5.37383356206639E-07" ixy="-2.55982277048139E-10" ixz="-2.95024709322941E-11" iyy="2.03576113009439E-07" iyz="-6.20176632030851E-08" izz="5.63158597281292E-07"/>
    </inertial>
    <visual>
      <origin rpy="0 0 0" xyz="0 0 0"/>
      <geometry>
        <mesh filename="package://Assem_w_tip_w_wrist/meshes/I_DIP.STL"/>
      </geometry>
      <material name="">
        <color rgba="0.796078431372549 0.823529411764706 0.937254901960784 1"/>
      </material>
    </visual>
    <collision>
      <origin rpy="0 0 0" xyz="0 0 0"/>
      <geometry>
        <mesh filename="package://Assem_w_tip_w_wrist/meshes/I_DIP.STL"/>
      </geometry>
    </collision>
  </link>
  <joint name="Index_DIP" type="revolute">
    <origin rpy="0 0 0" xyz="0 0.0280000000000003 0"/>
    <parent link="I_PIP"/>
    <child link="I_DIP"/>
    <axis xyz="-1 0 0"/>
    <limit effort="0" lower="-1.1885" upper="0" velocity="0"/>
  </joint>
  <link name="I_DIP_Tip">
    <inertial>
      <origin rpy="0 0 0" xyz="-1.79511198905996E-05 -0.0208456920790837 -0.00112546160039845"/>
      <mass value="0.00401062518281372"/>
      <inertia ixx="5.37384300107463E-07" ixy="-2.55997853759538E-10" ixz="-2.95041885529222E-11" iyy="2.03576090196458E-07" iyz="-6.20177097517699E-08" izz="5.63159534023233E-07"/>
    </inertial>
    <visual>
      <origin rpy="0 0 0" xyz="0 0 0"/>
      <geometry>
        <mesh filename="package://Assem_w_tip_w_wrist/meshes/I_DIP_Tip.STL"/>
      </geometry>
      <material name="">
        <color rgba="0.796078431372549 0.823529411764706 0.937254901960784 1"/>
      </material>
    </visual>
    <collision>
      <origin rpy="0 0 0" xyz="0 0 0"/>
      <geometry>
        <mesh filename="package://Assem_w_tip_w_wrist/meshes/I_DIP_Tip.STL"/>
      </geometry>
    </collision>
  </link>
  <joint name="Index_DIP_Tip" type="fixed">
    <origin rpy="0 0 0" xyz="0 0.0394999999999937 0.00999999999992346"/>
    <parent link="I_DIP"/>
    <child link="I_DIP_Tip"/>
    <axis xyz="0 0 0"/>
  </joint>
  <link name="M_MCP">
    <inertial>
      <origin rpy="0 0 0" xyz="0.0101136051263437 0.0123174670813249 0.00573716287431845"/>
      <mass value="0.00272570618171821"/>
      <inertia ixx="3.60740313112994E-07" ixy="-4.98044373035369E-11" ixz="5.84099746234099E-11" iyy="2.49082011924943E-07" iyz="4.63135977780751E-08" izz="3.60045720563296E-07"/>
    </inertial>
    <visual>
      <origin rpy="0 0 0" xyz="0 0 0"/>
      <geometry>
        <mesh filename="package://Assem_w_tip_w_wrist/meshes/M_MCP.STL"/>
      </geometry>
      <material name="">
        <color rgba="0.796078431372549 0.823529411764706 0.937254901960784 1"/>
      </material>
    </visual>
    <collision>
      <origin rpy="0 0 0" xyz="0 0 0"/>
      <geometry>
        <mesh filename="package://Assem_w_tip_w_wrist/meshes/M_MCP.STL"/>
      </geometry>
    </collision>
  </link>
  <joint name="Middle_MCP" type="revolute">
    <origin rpy="0 0 0" xyz="0.000368685087286369 0.177450000000007 -0.00795178552457043"/>
    <parent link="Palm"/>
    <child link="M_MCP"/>
    <axis xyz="-1 0 0"/>
    <limit effort="0" lower="-1.7791" upper="0" velocity="0"/>
  </joint>
  <link name="M_PIP">
    <inertial>
      <origin rpy="0 0 0" xyz="0.0101119553037649 0.010252203532493 0.00631460697183711"/>
      <mass value="0.00237659295556983"/>
      <inertia ixx="2.36204818756337E-07" ixy="1.76280077969291E-12" ixz="3.6770946859238E-11" iyy="2.02624438695474E-07" iyz="3.74104602859201E-09" izz="2.28946207305512E-07"/>
    </inertial>
    <visual>
      <origin rpy="0 0 0" xyz="0 0 0"/>
      <geometry>
        <mesh filename="package://Assem_w_tip_w_wrist/meshes/M_PIP.STL"/>
      </geometry>
      <material name="">
        <color rgba="0.792156862745098 0.819607843137255 0.933333333333333 1"/>
      </material>
    </visual>
    <collision>
      <origin rpy="0 0 0" xyz="0 0 0"/>
      <geometry>
        <mesh filename="package://Assem_w_tip_w_wrist/meshes/M_PIP.STL"/>
      </geometry>
    </collision>
  </link>
  <joint name="Middle_PIP" type="revolute">
    <origin rpy="0 0 0" xyz="0 0.0349845407392164 4.41133227957469E-05"/>
    <parent link="M_MCP"/>
    <child link="M_PIP"/>
    <axis xyz="-1 0 0"/>
    <limit effort="0" lower="-1.2823" upper="0" velocity="0"/>
  </joint>
  <link name="M_DIP">
    <inertial>
      <origin rpy="0 0 0" xyz="0.00959086211352167 0.0186497160542034 0.0088256380117765"/>
      <mass value="0.00393985712726044"/>
      <inertia ixx="5.33501047208565E-07" ixy="-2.54142134600127E-10" ixz="-2.39215092139354E-11" iyy="2.021617042524E-07" iyz="-6.16508472153486E-08" izz="5.59715605803219E-07"/>
    </inertial>
    <visual>
      <origin rpy="0 0 0" xyz="0 0 0"/>
      <geometry>
        <mesh filename="package://Assem_w_tip_w_wrist/meshes/M_DIP.STL"/>
      </geometry>
      <material name="">
        <color rgba="0.796078431372549 0.823529411764706 0.937254901960784 1"/>
      </material>
    </visual>
    <collision>
      <origin rpy="0 0 0" xyz="0 0 0"/>
      <geometry>
        <mesh filename="package://Assem_w_tip_w_wrist/meshes/M_DIP.STL"/>
      </geometry>
    </collision>
  </link>
  <joint name="Middle_DIP" type="revolute">
    <origin rpy="0 0 0" xyz="0.000522164976606988 0.0280000000000001 0"/>
    <parent link="M_PIP"/>
    <child link="M_DIP"/>
    <axis xyz="-1 0 0"/>
    <limit effort="0" lower="-1.275" upper="0" velocity="0"/>
  </joint>
  <link name="M_DIP_Tip">
    <inertial>
      <origin rpy="0 0 0" xyz="-1.82883264406922E-05 -0.0208502708482803 -0.00117436108513081"/>
      <mass value="0.00393986040390953"/>
      <inertia ixx="5.33501938359617E-07" ixy="-2.54105674461358E-10" ixz="-2.39229374183927E-11" iyy="2.02161687109717E-07" iyz="-6.16509173250593E-08" izz="5.59716482402493E-07"/>
    </inertial>
    <visual>
      <origin rpy="0 0 0" xyz="0 0 0"/>
      <geometry>
        <mesh filename="package://Assem_w_tip_w_wrist/meshes/M_DIP_Tip.STL"/>
      </geometry>
      <material name="">
        <color rgba="0.796078431372549 0.823529411764706 0.937254901960784 1"/>
      </material>
    </visual>
    <collision>
      <origin rpy="0 0 0" xyz="0 0 0"/>
      <geometry>
        <mesh filename="package://Assem_w_tip_w_wrist/meshes/M_DIP_Tip.STL"/>
      </geometry>
    </collision>
  </link>
  <joint name="Middle_DIP_Tip" type="fixed">
    <origin rpy="0 0 0" xyz="0.00960914993574263 0.0394999999999935 0.00999999999987842"/>
    <parent link="M_DIP"/>
    <child link="M_DIP_Tip"/>
    <axis xyz="0 0 0"/>
  </joint>
  <link name="R_B_MCP">
    <inertial>
      <origin rpy="0 0 0" xyz="0.000141400022333087 0.00748571390330743 -0.00336921468308588"/>
      <mass value="0.00533806254719223"/>
      <inertia ixx="1.0353483169865E-06" ixy="-2.71242837104229E-09" ixz="5.52800342769745E-09" iyy="6.29683236201212E-07" iyz="3.28505949538031E-07" izz="8.39889436289043E-07"/>
    </inertial>
    <visual>
      <origin rpy="0 0 0" xyz="0 0 0"/>
      <geometry>
        <mesh filename="package://Assem_w_tip_w_wrist/meshes/R_B_MCP.STL"/>
      </geometry>
      <material name="">
        <color rgba="0.698039215686274 0.698039215686274 0.698039215686274 1"/>
      </material>
    </visual>
    <collision>
      <origin rpy="0 0 0" xyz="0 0 0"/>
      <geometry>
        <mesh filename="package://Assem_w_tip_w_wrist/meshes/R_B_MCP.STL"/>
      </geometry>
    </collision>
  </link>
  <joint name="Ring_Below_MCP" type="revolute">
    <origin rpy="0 0 0" xyz="-0.0105000000003218 0.140450000000007 0"/>
    <parent link="Palm"/>
    <child link="R_B_MCP"/>
    <axis xyz="0 0 1"/>
    <limit effort="0" lower="0" upper="0.4666" velocity="0"/>
  </joint>
  <link name="R_MCP">
    <inertial>
      <origin rpy="0 0 0" xyz="-1.81900103362071E-05 0.0123593679217145 0.00587054972046028"/>
      <mass value="0.00276771907047308"/>
      <inertia ixx="3.6293319421358E-07" ixy="-2.60044174910396E-11" ixz="4.37098756345083E-11" iyy="2.51940196800613E-07" iyz="4.48500665923026E-08" izz="3.63178593785227E-07"/>
    </inertial>
    <visual>
      <origin rpy="0 0 0" xyz="0 0 0"/>
      <geometry>
        <mesh filename="package://Assem_w_tip_w_wrist/meshes/R_MCP.STL"/>
      </geometry>
      <material name="">
        <color rgba="0.796078431372549 0.823529411764706 0.937254901960784 1"/>
      </material>
    </visual>
    <collision>
      <origin rpy="0 0 0" xyz="0 0 0"/>
      <geometry>
        <mesh filename="package://Assem_w_tip_w_wrist/meshes/R_MCP.STL"/>
      </geometry>
    </collision>
  </link>
  <joint name="Ring_MCP" type="revolute">
    <origin rpy="0 0 0" xyz="0 0.0280000000000001 -0.00795476324525061"/>
    <parent link="R_B_MCP"/>
    <child link="R_MCP"/>
    <axis xyz="-1 0 0"/>
    <limit effort="0" lower="-1.7553" upper="0" velocity="0"/>
  </joint>
  <link name="R_PIP">
    <inertial>
      <origin rpy="0 0 0" xyz="-1.80413738349317E-05 0.0102929994545149 0.00630507414295918"/>
      <mass value="0.00238434024010653"/>
      <inertia ixx="2.36356872842794E-07" ixy="-6.39117308852323E-12" ixz="1.54530706119539E-11" iyy="2.03192454048864E-07" iyz="3.38662038008827E-09" izz="2.30526732864084E-07"/>
    </inertial>
    <visual>
      <origin rpy="0 0 0" xyz="0 0 0"/>
      <geometry>
        <mesh filename="package://Assem_w_tip_w_wrist/meshes/R_PIP.STL"/>
      </geometry>
      <material name="">
        <color rgba="0.796078431372549 0.823529411764706 0.937254901960784 1"/>
      </material>
    </visual>
    <collision>
      <origin rpy="0 0 0" xyz="0 0 0"/>
      <geometry>
        <mesh filename="package://Assem_w_tip_w_wrist/meshes/R_PIP.STL"/>
      </geometry>
    </collision>
  </link>
  <joint name="Ring_PIP" type="revolute">
    <origin rpy="0 0 0" xyz="0 0.0349845407392165 4.41133228030188E-05"/>
    <parent link="R_MCP"/>
    <child link="R_PIP"/>
    <axis xyz="-1 0 0"/>
    <limit effort="0" lower="-1.273" upper="0" velocity="0"/>
  </joint>
  <link name="R_DIP">
    <inertial>
      <origin rpy="0 0 0" xyz="-1.83063200351503E-05 0.0186629542830772 0.00880902120918689"/>
      <mass value="0.00392874530194357"/>
      <inertia ixx="5.33045587126399E-07" ixy="-2.55761115191706E-10" ixz="-2.41673457656617E-11" iyy="2.01758989610719E-07" iyz="-6.18614962583378E-08" izz="5.59544610351373E-07"/>
    </inertial>
    <visual>
      <origin rpy="0 0 0" xyz="0 0 0"/>
      <geometry>
        <mesh filename="package://Assem_w_tip_w_wrist/meshes/R_DIP.STL"/>
      </geometry>
      <material name="">
        <color rgba="0.796078431372549 0.823529411764706 0.937254901960784 1"/>
      </material>
    </visual>
    <collision>
      <origin rpy="0 0 0" xyz="0 0 0"/>
      <geometry>
        <mesh filename="package://Assem_w_tip_w_wrist/meshes/R_DIP.STL"/>
      </geometry>
    </collision>
  </link>
  <joint name="Ring_DIP" type="revolute">
    <origin rpy="0 0 0" xyz="0 0.0280000000000001 0"/>
    <parent link="R_PIP"/>
    <child link="R_DIP"/>
    <axis xyz="-1 0 0"/>
    <limit effort="0" lower="-1.2842" upper="0" velocity="0"/>
  </joint>
  <link name="R_DIP_Tip">
    <inertial>
      <origin rpy="0 0 0" xyz="-1.83070900889835E-05 -0.0208370357672115 -0.00119097963723128"/>
      <mass value="0.00392874776267662"/>
      <inertia ixx="5.33046262768438E-07" ixy="-2.55706763585683E-10" ixz="-2.41593657796156E-11" iyy="2.01758966180991E-07" iyz="-6.18614331450794E-08" izz="5.59545275993907E-07"/>
    </inertial>
    <visual>
      <origin rpy="0 0 0" xyz="0 0 0"/>
      <geometry>
        <mesh filename="package://Assem_w_tip_w_wrist/meshes/R_DIP_Tip.STL"/>
      </geometry>
      <material name="">
        <color rgba="0.796078431372549 0.823529411764706 0.937254901960784 1"/>
      </material>
    </visual>
    <collision>
      <origin rpy="0 0 0" xyz="0 0 0"/>
      <geometry>
        <mesh filename="package://Assem_w_tip_w_wrist/meshes/R_DIP_Tip.STL"/>
      </geometry>
    </collision>
  </link>
  <joint name="Ring_DIP_Tip" type="fixed">
    <origin rpy="0 0 0" xyz="0 0.0394999999999934 0.010000000000021"/>
    <parent link="R_DIP"/>
    <child link="R_DIP_Tip"/>
    <axis xyz="0 0 0"/>
  </joint>
  <link name="P_B_MCP">
    <inertial>
      <origin rpy="0 0 0" xyz="-0.00016822714604979 0.00805589897466968 -0.00365488797406816"/>
      <mass value="0.00512816464445928"/>
      <inertia ixx="9.99698557475322E-07" ixy="-2.1827834732298E-08" ixz="1.56085772722901E-08" iyy="6.10313699095437E-07" iyz="3.14479371654659E-07" izz="7.98354669674153E-07"/>
    </inertial>
    <visual>
      <origin rpy="0 0 0" xyz="0 0 0"/>
      <geometry>
        <mesh filename="package://Assem_w_tip_w_wrist/meshes/P_B_MCP.STL"/>
      </geometry>
      <material name="">
        <color rgba="0.698039215686274 0.698039215686274 0.698039215686274 1"/>
      </material>
    </visual>
    <collision>
      <origin rpy="0 0 0" xyz="0 0 0"/>
      <geometry>
        <mesh filename="package://Assem_w_tip_w_wrist/meshes/P_B_MCP.STL"/>
      </geometry>
    </collision>
  </link>
  <joint name="Pinky_Below_MCP" type="revolute">
    <origin rpy="0 0 0" xyz="-0.0315000000003377 0.140450000000008 0"/>
    <parent link="Palm"/>
    <child link="P_B_MCP"/>
    <axis xyz="0 0 1"/>
    <limit effort="0" lower="0" upper="0.6872" velocity="0"/>
  </joint>
  <link name="P_MCP">
    <inertial>
      <origin rpy="0 0 0" xyz="-1.75508168624786E-05 0.0123862716758279 0.00586908713083029"/>
      <mass value="0.0027527409670799"/>
      <inertia ixx="3.66134185519609E-07" ixy="-5.23805936563049E-11" ixz="5.22078287918388E-11" iyy="2.51982271717664E-07" iyz="4.56227552560376E-08" izz="3.63835231591852E-07"/>
    </inertial>
    <visual>
      <origin rpy="0 0 0" xyz="0 0 0"/>
      <geometry>
        <mesh filename="package://Assem_w_tip_w_wrist/meshes/P_MCP.STL"/>
      </geometry>
      <material name="">
        <color rgba="0.796078431372549 0.823529411764706 0.937254901960784 1"/>
      </material>
    </visual>
    <collision>
      <origin rpy="0 0 0" xyz="0 0 0"/>
      <geometry>
        <mesh filename="package://Assem_w_tip_w_wrist/meshes/P_MCP.STL"/>
      </geometry>
    </collision>
  </link>
  <joint name="Pinky_MCP" type="revolute">
    <origin rpy="0 0 0" xyz="0 0.028 -0.00795476324526755"/>
    <parent link="P_B_MCP"/>
    <child link="P_MCP"/>
    <axis xyz="-1 0 0"/>
    <limit effort="0" lower="-1.7269" upper="0" velocity="0"/>
  </joint>
  <link name="P_PIP">
    <inertial>
      <origin rpy="0 0 0" xyz="-1.72400883345983E-05 0.0103223722971154 0.00635348178219377"/>
      <mass value="0.0023789537359218"/>
      <inertia ixx="2.36329510859284E-07" ixy="1.94423826737988E-11" ixz="6.59154956290154E-11" iyy="2.03127917135172E-07" iyz="3.65773511125615E-09" izz="2.30951832349696E-07"/>
    </inertial>
    <visual>
      <origin rpy="0 0 0" xyz="0 0 0"/>
      <geometry>
        <mesh filename="package://Assem_w_tip_w_wrist/meshes/P_PIP.STL"/>
      </geometry>
      <material name="">
        <color rgba="0.796078431372549 0.823529411764706 0.937254901960784 1"/>
      </material>
    </visual>
    <collision>
      <origin rpy="0 0 0" xyz="0 0 0"/>
      <geometry>
        <mesh filename="package://Assem_w_tip_w_wrist/meshes/P_PIP.STL"/>
      </geometry>
    </collision>
  </link>
  <joint name="Pinky_PIP" type="revolute">
    <origin rpy="0 0 0" xyz="0 0.0349845407392164 4.41133227925272E-05"/>
    <parent link="P_MCP"/>
    <child link="P_PIP"/>
    <axis xyz="-1 0 0"/>
    <limit effort="0" lower="-1.2573" upper="0" velocity="0"/>
  </joint>
  <link name="P_DIP">
    <inertial>
      <origin rpy="0 0 0" xyz="-2.31261467509292E-05 0.0152163388924308 0.00857258033935445"/>
      <mass value="0.00310861773436295"/>
      <inertia ixx="3.022016992443E-07" ixy="-7.85953119521502E-12" ixz="-7.08752879404416E-12" iyy="1.56377778235913E-07" iyz="-4.50241177337849E-08" izz="3.21156101863139E-07"/>
    </inertial>
    <visual>
      <origin rpy="0 0 0" xyz="0 0 0"/>
      <geometry>
        <mesh filename="package://Assem_w_tip_w_wrist/meshes/P_DIP.STL"/>
      </geometry>
      <material name="">
        <color rgba="0.796078431372549 0.823529411764706 0.937254901960784 1"/>
      </material>
    </visual>
    <collision>
      <origin rpy="0 0 0" xyz="0 0 0"/>
      <geometry>
        <mesh filename="package://Assem_w_tip_w_wrist/meshes/P_DIP.STL"/>
      </geometry>
    </collision>
  </link>
  <joint name="Pinky_DIP" type="revolute">
    <origin rpy="0 0 0" xyz="0 0.028 0"/>
    <parent link="P_PIP"/>
    <child link="P_DIP"/>
    <axis xyz="-1 0 0"/>
    <limit effort="0" lower="-1.2577" upper="0" velocity="0"/>
  </joint>
  <link name="P_DIP_Tip">
    <inertial>
      <origin rpy="0 0 0" xyz="-2.31260801152391E-05 -0.0152836637237333 -0.00142741970512751"/>
      <mass value="0.00310861698058435"/>
      <inertia ixx="3.02201602388332E-07" ixy="-7.86299305832725E-12" ixz="-7.08594985067307E-12" iyy="1.56377785358377E-07" iyz="-4.50241170067936E-08" izz="3.21156006007108E-07"/>
    </inertial>
    <visual>
      <origin rpy="0 0 0" xyz="0 0 0"/>
      <geometry>
        <mesh filename="package://Assem_w_tip_w_wrist/meshes/P_DIP_Tip.STL"/>
      </geometry>
      <material name="">
        <color rgba="0.796078431372549 0.823529411764706 0.937254901960784 1"/>
      </material>
    </visual>
    <collision>
      <origin rpy="0 0 0" xyz="0 0 0"/>
      <geometry>
        <mesh filename="package://Assem_w_tip_w_wrist/meshes/P_DIP_Tip.STL"/>
      </geometry>
    </collision>
  </link>
  <joint name="Pinky_DIP_Tip" type="fixed">
    <origin rpy="0 0 0" xyz="0 0.0304999999999933 0.0100000000000567"/>
    <parent link="P_DIP"/>
    <child link="P_DIP_Tip"/>
    <axis xyz="0 0 0"/>
  </joint>
  <link name="T_P_S">
    <inertial>
      <origin rpy="0 0 0" xyz="-0.00133532824825168 0.000120665991595326 0.000406645795163037"/>
      <mass value="0.0104013413375586"/>
      <inertia ixx="5.42061188311911E-07" ixy="2.5306807659414E-08" ixz="-9.78380508419395E-08" iyy="3.50375398539094E-06" iyz="-7.00108296291377E-10" izz="3.27135341594506E-06"/>
    </inertial>
    <visual>
      <origin rpy="0 0 0" xyz="0 0 0"/>
      <geometry>
        <mesh filename="package://Assem_w_tip_w_wrist/meshes/T_P_S.STL"/>
      </geometry>
      <material name="">
        <color rgba="1 0.752941176470588 0.752941176470588 1"/>
      </material>
    </visual>
    <collision>
      <origin rpy="0 0 0" xyz="0 0 0"/>
      <geometry>
        <mesh filename="package://Assem_w_tip_w_wrist/meshes/T_P_S.STL"/>
      </geometry>
    </collision>
  </link>
  <joint name="Thumb_Pro_Supination" type="revolute">
    <origin rpy="0 0 0" xyz="0 0.0700500000000081 0.00254523675472768"/>
    <parent link="Palm"/>
    <child link="T_P_S"/>
    <axis xyz="1 0 0"/>
    <limit effort="0" lower="-0.6363" upper="0.6363" velocity="0"/>
  </joint>
  <link name="T_CMC">
    <inertial>
      <origin rpy="0 0 0" xyz="0.00168374953213787 9.82021480901013E-05 0.0218902393318586"/>
      <mass value="0.0056356338651766"/>
      <inertia ixx="1.26829163436478E-06" ixy="1.05367080871463E-08" ixz="-1.62375355325856E-07" iyy="1.22011213798707E-06" iyz="-2.03542243169219E-08" izz="5.81959418465577E-07"/>
    </inertial>
    <visual>
      <origin rpy="0 0 0" xyz="0 0 0"/>
      <geometry>
        <mesh filename="package://Assem_w_tip_w_wrist/meshes/T_CMC.STL"/>
      </geometry>
      <material name="">
        <color rgba="0 1 0 1"/>
      </material>
    </visual>
    <collision>
      <origin rpy="0 0 0" xyz="0 0 0"/>
      <geometry>
        <mesh filename="package://Assem_w_tip_w_wrist/meshes/T_CMC.STL"/>
      </geometry>
    </collision>
  </link>
  <joint name="Thumb_CMC" type="revolute">
    <origin rpy="-1.07907624681628 0.636866640194575 -1.26244557315784" xyz="0.0241199999998295 0 0.0115599999996668"/>
    <parent link="T_P_S"/>
    <child link="T_CMC"/>
    <axis xyz="0.76604444311898 -0.642787609686537 0"/>
    <limit effort="0" lower="0" upper="1.8545" velocity="0"/>
  </joint>
  <link name="T_MCP">
    <inertial>
      <origin rpy="0 0 0" xyz="-0.00410352367274976 -0.0188546486561465 -0.000135076165763207"/>
      <mass value="0.00332373832910088"/>
      <inertia ixx="5.47690075970923E-07" ixy="-3.0661509593922E-08" ixz="1.57099424813818E-10" iyy="3.25193587156607E-07" iyz="4.33023893224048E-11" izz="5.3410848735595E-07"/>
    </inertial>
    <visual>
      <origin rpy="0 0 0" xyz="0 0 0"/>
      <geometry>
        <mesh filename="package://Assem_w_tip_w_wrist/meshes/T_MCP.STL"/>
      </geometry>
      <material name="">
        <color rgba="1 1 1 1"/>
      </material>
    </visual>
    <collision>
      <origin rpy="0 0 0" xyz="0 0 0"/>
      <geometry>
        <mesh filename="package://Assem_w_tip_w_wrist/meshes/T_MCP.STL"/>
      </geometry>
    </collision>
  </link>
  <joint name="Thumb_MCP" type="revolute">
    <origin rpy="-1.5707963267949 -0.240680903850004 0" xyz="0.0106391616042632 0 0.0519999941010939"/>
    <parent link="T_CMC"/>
    <child link="T_MCP"/>
    <axis xyz="0 0 1"/>
    <limit effort="0" lower="-1.3527" upper="0" velocity="0"/>
  </joint>
  <link name="T_IP">
    <inertial>
      <origin rpy="0 0 0" xyz="-0.00960947729713725 -0.000136820949692695 0.0166952338081086"/>
      <mass value="0.00421936396456514"/>
      <inertia ixx="5.7343758975226E-07" ixy="-2.42228731253459E-10" ixz="1.0905764708893E-07" iyy="5.79569688739935E-07" iyz="1.39216154169752E-10" izz="3.12842620211569E-07"/>
    </inertial>
    <visual>
      <origin rpy="0 0 0" xyz="0 0 0"/>
      <geometry>
        <mesh filename="package://Assem_w_tip_w_wrist/meshes/T_IP.STL"/>
      </geometry>
      <material name="">
        <color rgba="1 1 1 1"/>
      </material>
    </visual>
    <collision>
      <origin rpy="0 0 0" xyz="0 0 0"/>
      <geometry>
        <mesh filename="package://Assem_w_tip_w_wrist/meshes/T_IP.STL"/>
      </geometry>
    </collision>
  </link>
  <joint name="Thumb_IP" type="revolute">
    <origin rpy="1.5707963267949 0 -0.0694641042293598" xyz="0 -0.0399999999999966 0"/>
    <parent link="T_MCP"/>
    <child link="T_IP"/>
    <axis xyz="0 1 0"/>
    <limit effort="0" lower="-0.56343" upper="0" velocity="0"/>
  </joint>
  <link name="T_IP_Tip">
    <inertial>
      <origin rpy="0 0 0" xyz="0.00733993695116229 6.49316572202963E-06 -0.0155735597915196"/>
      <mass value="0.00421936396456506"/>
      <inertia ixx="5.73437589752248E-07" ixy="-2.42228731254412E-10" ixz="1.09057647088929E-07" iyy="5.79569688739923E-07" iyz="1.3921615417177E-10" izz="3.12842620211567E-07"/>
    </inertial>
    <visual>
      <origin rpy="0 0 0" xyz="0 0 0"/>
      <geometry>
        <mesh filename="package://Assem_w_tip_w_wrist/meshes/T_IP_Tip.STL"/>
      </geometry>
      <material name="">
        <color rgba="1 1 1 1"/>
      </material>
    </visual>
    <collision>
      <origin rpy="0 0 0" xyz="0 0 0"/>
      <geometry>
        <mesh filename="package://Assem_w_tip_w_wrist/meshes/T_IP_Tip.STL"/>
      </geometry>
    </collision>
  </link>
  <joint name="Thumb_IP_Tip" type="fixed">
    <origin rpy="0 0 0" xyz="-0.016949414248298 -0.000143314115411422 0.0322687935996243"/>
    <parent link="T_IP"/>
    <child link="T_IP_Tip"/>
    <axis xyz="0 0 0"/>
  </joint>
  <link name="palm_intermediate_link"/>
  <joint name="Wrist_Flex_Extension" type="revolute">
    <parent link="base_link"/>
    <child link="palm_intermediate_link"/>
    <origin rpy="1.5707963267949 0 1.5707963267949" xyz="0.00633660798242791 0 0.108612"/>
    <axis xyz="1 0 0"/>
    <limit effort="1" lower="-0.907" upper="0.907" velocity="1"/>
  </joint>
  <joint name="Wrist_RUD" type="revolute">
    <parent link="palm_intermediate_link"/>
    <child link="Palm"/>
    <origin rpy="0 0 0" xyz="0 0 0"/>
    <axis xyz="0 0 1"/>
    <limit effort="1" lower="-0.314" upper="0.314" velocity="1"/>
  </joint>
  <link name="world"/>
  <joint name="world_joint" type="fixed">
    <parent link="world"/>
    <child link="base_link"/>
    <origin rpy="0 0 0" xyz="0 0 0"/>
  </joint>
  <joint name="connect" type="fixed">
    <parent link="wrist3_Link"/>
    <child link="palm_intermediate_link"/>
    <origin rpy="0 0 0" xyz="0 0 0.02"/>
  </joint>
</robot>

